<?xml version="1.0"?>
<robot xmlns:xacro="http://www.ros.org/wiki/xacro" name="navvis">
    <!-- base !-->
    <link name="base">
        <visual>
            <origin xyz = "0.0 0.0 0.96" rpy="0.0 0.0 0.0"/>
            <geometry>
                <box size="0.45 0.78 1.92" />
            </geometry>
        </visual>
        <collision>
            <origin xyz = "0.0 0.0 0.96" rpy="0.0 0.0 0.0"/>
            <geometry>
                <box size="0.45 0.78 1.92" />
            </geometry>
        </collision>
    </link>

    <xacro:macro name="xacro_name" params="side reflect">
        <link name="wheel_${side}">
            <visual>
                <geometry>
                    <cylinder radius="0.2" length="0.05" />
                </geometry>
            </visual>
            <collision>
                <geometry>
                    <cylinder radius="0.2" length="0.05" />
                </geometry>
            </collision>
        </link>

        <joint name="base_wheel_${side}_joint" type="continuous">
            <parent link="base"/>
            <child link="wheel_${side}" />
            <!-- -1.5708 corresponding to half pi !-->
            <origin xyz="-0.10 ${ reflect * 0.4 } 0.0" rpy="-1.5708 0.0 0.0" />
            <axis xyz="0 0 1" />
        </joint>
        
    </xacro:macro>
    <xacro:xacro_name side="left" reflect="1" />
    <xacro:xacro_name side="right" reflect="-1"/>

    <link name="wheel_center">
        <visual>
            <geometry>
                <cylinder radius="0.15" length="0.05" />
            </geometry>
        </visual>
        <collision>
            <geometry>
                <cylinder radius="0.15" length="0.05" />
            </geometry>
        </collision>
    </link>

    <joint name="base_wheel_center_joint" type="continuous">
        <parent link="base"/>
        <child link="wheel_center" />
        <!-- -1.5708 corresponding to half pi !-->
        <origin xyz="0.10 0.0 -0.05" rpy="-1.5708 0.0 0.0" />
        <axis xyz="0 0 1" />
    </joint>

    <xacro:include filename="$(find gazebo_plugins)/test/multi_robot_scenario/xacro/laser/hokuyo.xacro" />
    <xacro:laser 
        name="laser_vert_bottom" 
        parent="base" 
        xyz="0.315789 -0.002068 0.510000" 
        rpy="3.135475 -1.304500 0.002466" 
        meshes="package://gazebo_plugins/test/multi_robot_scenario/meshes/laser" />

    <xacro:laser 
        name="laser_vert_top_left" 
        parent="base" 
        xyz="0.2997 0.1531 1.8443" 
        rpy="1.1780 0.6198 1.9560" 
        meshes="package://gazebo_plugins/test/multi_robot_scenario/meshes/laser" />
    
    <xacro:laser 
        name="laser_vert_top_right" 
        parent="base" 
        xyz="0.2978 -0.1450 1.8451" 
        rpy="-1.760 0.6313 -1.9377"
        meshes="package://gazebo_plugins/test/multi_robot_scenario/meshes/laser" />

    <xacro:include filename="$(find velodyne_description)/urdf/VLP-16.urdf.xacro" />
    <xacro:VLP-16 
    	parent="base" 
    	name="laser_horiz" 
    	topic="laser_horiz/packets" 
    	hz="10" samples="440" 
    	gpu="true">
        <origin xyz="0.2325 0.0001 1.9201" rpy="-0.0012 0.1146 -0.0015" />
    </xacro:VLP-16>

</robot>
